Workbook

Sheet README
A1: Metallic Glass GFA Multisource Database — Canonical V1
A3: Field | B3: Definition
A4: Canonical file | B4: Metallic_Glass_GFA_Multisource_Database_V1.xlsx
A5: Scope | B5: Reconstruction and audit of the 276 observations announced in the draft manuscript.
A6: Rule 1 | B6: No numerical value is entered as VERIFIED unless traceable to a primary source/table/page or authoritative full text.
A7: Rule 2 | B7: Suspected typographical corrections from the draft remain claims until primary-source verification.
A8: Rule 3 | B8: One row = one identifiable experimental observation; repeated nominal compositions are retained as separate observations when source/conditions differ.
A9: Rule 4 | B9: Derived descriptors are calculated from primary temperatures; source-reported derived values are preserved separately for audit.
A10: Current status | B10: V1 structure created; primary-source registry initiated. The 276-row reconstruction is not yet claimed complete.

Sheet Master_Database
A1: MG_ID | B1: Composition_raw | C1: Composition_normalized | D1: Family | E1: Subfamily | F1: Tg_K | G1: Tx_K | H1: Tm_K | I1: Tl_K | J1: dc_mm | K1: Critical_thickness_mm | L1: Critical_cooling_rate_K_s | M1: Casting_method | N1: Sample_geometry | O1: Source_ID | P1: DOI | Q1: Source_table_page | R1: Value_status | S1: QC_status | T1: Correction_flag | U1: Correction_note | V1: Include_model | W1: Notes
A2: MG-ZNA-001 | B2: Ni3Zr10Al1 | C2: Al8.3Ni25.0Zr66.7 | D2: Zr–Ni–Al | E2: Al–Ni–Zr | F2: 663 | G2: 710 | H2: 1199 | I2: 1236 | M2: Copper mold suction casting | N2: Rod | O2: SRC37 | P2: 10.1007/s11434-011-4842-z | Q2: Primary full-text table | R2: VERIFIED_PRIMARY | S2: PASS | T2: YES | U2: Exact Tg/Tx/Tm/Tl tuple verified in primary full-text table. | V2: YES | W2: Primary numerical verification completed; composition normalized from table atomic percentages.
A3: MG-ZNA-002 | B3: Ni3Zr10Al1.5 | C3: Al12.0Ni24.0Zr64.0 | D3: Zr–Ni–Al | E3: Al–Ni–Zr | F3: 682 | G3: 729 | H3: 1174 | I3: 1283 | M3: Copper mold suction casting | N3: Rod | O3: SRC37 | P3: 10.1007/s11434-011-4842-z | Q3: Primary full-text table | R3: VERIFIED_PRIMARY | S3: PASS | T3: YES | U3: Exact Tg/Tx/Tm/Tl tuple verified in primary full-text table. | V3: YES | W3: Primary numerical verification completed; composition normalized from table atomic percentages.
A4: MG-ZNA-003 | B4: Ni3Zr10Al2 | C4: Al15.4Ni23.1Zr61.5 | D4: Zr–Ni–Al | E4: Al–Ni–Zr | F4: 703 | G4: 758 | H4: 1178 | I4: 1266 | M4: Copper mold suction casting | N4: Rod | O4: SRC37 | P4: 10.1007/s11434-011-4842-z | Q4: Primary full-text table | R4: VERIFIED_PRIMARY | S4: PASS | T4: YES | U4: Exact Tg/Tx/Tm/Tl tuple verified in primary full-text table. | V4: YES | W4: Primary numerical verification completed; composition normalized from table atomic percentages.
A5: MG-ZNA-004 | B5: Ni3Zr10Al3 | C5: Al21.4Ni21.4Zr57.2 | D5: Zr–Ni–Al | E5: Al–Ni–Zr | F5: 745 | G5: 784 | H5: 1183 | I5: 1342 | M5: Copper mold suction casting | N5: Rod | O5: SRC37 | P5: 10.1007/s11434-011-4842-z | Q5: Primary full-text table | R5: VERIFIED_PRIMARY | S5: PASS | T5: YES | U5: Exact Tg/Tx/Tm/Tl tuple verified in primary full-text table. | V5: YES | W5: Primary numerical verification completed; composition normalized from table atomic percentages.
A6: MG-ZNA-005 | B6: Ni3Zr9Al1 | C6: Al9.1Ni27.3Zr63.6 | D6: Zr–Ni–Al | E6: Al–Ni–Zr | F6: 680 | G6: 721 | H6: 1178 | I6: 1220 | M6: Copper mold suction casting | N6: Rod | O6: SRC37 | P6: 10.1007/s11434-011-4842-z | Q6: Primary full-text table | R6: VERIFIED_PRIMARY | S6: PASS | T6: YES | U6: Exact Tg/Tx/Tm/Tl tuple verified in primary full-text table. | V6: YES | W6: Primary numerical verification completed; composition normalized from table atomic percentages.
A7: MG-ZNA-006 | B7: Ni3Zr9Al1.5 | C7: Al13.0Ni26.0Zr61.0 | D7: Zr–Ni–Al | E7: Al–Ni–Zr | F7: 702 | G7: 770 | H7: 1176 | I7: 1263 | M7: Copper mold suction casting | N7: Rod | O7: SRC37 | P7: 10.1007/s11434-011-4842-z | Q7: Primary full-text table | R7: VERIFIED_PRIMARY | S7: PASS | T7: YES | U7: Exact Tg/Tx/Tm/Tl tuple verified in primary full-text table. | V7: YES | W7: Primary numerical verification completed; composition normalized from table atomic percentages.
A8: MG-ZNA-007 | B8: Ni3Zr9Al2 | C8: Al16.7Ni25.0Zr58.3 | D8: Zr–Ni–Al | E8: Al–Ni–Zr | F8: 721 | G8: 789 | H8: 1185 | I8: 1289 | M8: Copper mold suction casting | N8: Rod | O8: SRC37 | P8: 10.1007/s11434-011-4842-z | Q8: Primary full-text table | R8: VERIFIED_PRIMARY | S8: PASS | T8: YES | U8: Exact Tg/Tx/Tm/Tl tuple verified in primary full-text table. | V8: YES | W8: Primary numerical verification completed; composition normalized from table atomic percentages.
A9: MG-ZNA-008 | B9: Ni3Zr9Al3 | C9: Al23.1Ni23.1Zr53.8 | D9: Zr–Ni–Al | E9: Al–Ni–Zr | F9: 772 | G9: 813 | H9: 1182 | I9: 1338 | M9: Copper mold suction casting | N9: Rod | O9: SRC37 | P9: 10.1007/s11434-011-4842-z | Q9: Primary full-text table | R9: VERIFIED_PRIMARY | S9: PASS | T9: YES | U9: Exact Tg/Tx/Tm/Tl tuple verified in primary full-text table. | V9: YES | W9: Primary numerical verification completed; composition normalized from table atomic percentages.
A10: MG-ZNA-009 | B10: Ni3Zr8Al1 | C10: Al7.1Ni28.6Zr64.3 | D10: Zr–Ni–Al | E10: Al–Ni–Zr | F10: 673 | G10: 706 | H10: 1178 | I10: 1244 | M10: Copper mold suction casting | N10: Rod | O10: SRC37 | P10: 10.1007/s11434-011-4842-z | Q10: Primary full-text table | R10: VERIFIED_PRIMARY | S10: PASS | T10: YES | U10: Exact Tg/Tx/Tm/Tl tuple verified in primary full-text table. | V10: YES | W10: Primary numerical verification completed; composition normalized from table atomic percentages.
A11: MG-ZNA-010 | B11: Ni3Zr8Al1.5 | C11: Al10.3Ni27.6Zr62.1 | D11: Zr–Ni–Al | E11: Al–Ni–Zr | F11: 691 | G11: 739 | H11: 1176 | I11: 1239 | M11: Copper mold suction casting | N11: Rod | O11: SRC37 | P11: 10.1007/s11434-011-4842-z | Q11: Primary full-text table | R11: VERIFIED_PRIMARY | S11: PASS | T11: YES | U11: Exact Tg/Tx/Tm/Tl tuple verified in primary full-text table. | V11: YES | W11: Primary numerical verification completed; composition normalized from table atomic percentages.
A12: MG-ZNA-011 | B12: Ni3Zr8Al2 | C12: Al13.3Ni26.7Zr60.0 | D12: Zr–Ni–Al | E12: Al–Ni–Zr | F12: 707 | G12: 775 | H12: 1179 | I12: 1222 | M12: Copper mold suction casting | N12: Rod | O12: SRC37 | P12: 10.1007/s11434-011-4842-z | Q12: Primary full-text table | R12: VERIFIED_PRIMARY | S12: PASS | T12: YES | U12: Exact Tg/Tx/Tm/Tl tuple verified in primary full-text table. | V12: YES | W12: Primary numerical verification completed; composition normalized from table atomic percentages.
A13: MG-ZNA-012 | B13: Ni3Zr8Al3 | C13: Al18.8Ni25.0Zr56.2 | D13: Zr–Ni–Al | E13: Al–Ni–Zr | F13: 742 | G13: 804 | H13: 1184 | I13: 1336 | M13: Copper mold suction casting | N13: Rod | O13: SRC37 | P13: 10.1007/s11434-011-4842-z | Q13: Primary full-text table | R13: VERIFIED_PRIMARY | S13: PASS | T13: YES | U13: Exact Tg/Tx/Tm/Tl tuple verified in primary full-text table. | V13: YES | W13: Primary numerical verification completed; composition normalized from table atomic percentages.
A14: MG-ZNA-013 | B14: Ni3Zr7Al1 | C14: Al9.1Ni27.3Zr63.6 | D14: Zr–Ni–Al | E14: Al–Ni–Zr | F14: 680 | G14: 721 | H14: 1178 | I14: 1220 | M14: Copper mold suction casting | N14: Rod | O14: SRC21 | P14: 10.1007/s11434-011-4842-z | Q14: Table 1, p.3906 | R14: VERIFIED_PRIMARY | S14: PASS | T14: NO | V14: PENDING | W14: Source Table 1
A15: MG-ZNA-014 | B15: Ni3Zr7Al1.5 | C15: Al13.0Ni26.0Zr61.0 | D15: Zr–Ni–Al | E15: Al–Ni–Zr | F15: 702 | G15: 770 | H15: 1176 | I15: 1263 | M15: Copper mold suction casting | N15: Rod | O15: SRC21 | P15: 10.1007/s11434-011-4842-z | Q15: Table 1, p.3906 | R15: VERIFIED_PRIMARY | S15: PASS | T15: NO | V15: PENDING | W15: Source Table 1
A16: MG-ZNA-015 | B16: Ni3Zr7Al2 | C16: Al16.7Ni25.0Zr58.3 | D16: Zr–Ni–Al | E16: Al–Ni–Zr | F16: 721 | G16: 789 | H16: 1185 | I16: 1289 | M16: Copper mold suction casting | N16: Rod | O16: SRC21 | P16: 10.1007/s11434-011-4842-z | Q16: Table 1, p.3906 | R16: VERIFIED_PRIMARY | S16: PASS | T16: NO | V16: PENDING | W16: Source Table 1
A17: MG-ZNA-016 | B17: Ni3Zr7Al3 | C17: Al23.1Ni23.1Zr53.8 | D17: Zr–Ni–Al | E17: Al–Ni–Zr | F17: 772 | G17: 813 | H17: 1182 | I17: 1338 | M17: Copper mold suction casting | N17: Rod | O17: SRC21 | P17: 10.1007/s11434-011-4842-z | Q17: Table 1, p.3906 | R17: VERIFIED_PRIMARY | S17: PASS | T17: NO | V17: PENDING | W17: Source Table 1
A18: MG-ZNA-017 | B18: Ni4Zr9Al1 | C18: Al7.1Ni28.6Zr64.3 | D18: Zr–Ni–Al | E18: Al–Ni–Zr | F18: 673 | G18: 706 | H18: 1178 | I18: 1244 | M18: Copper mold suction casting | N18: Rod | O18: SRC21 | P18: 10.1007/s11434-011-4842-z | Q18: Table 1, p.3906 | R18: VERIFIED_PRIMARY | S18: PASS | T18: NO | V18: PENDING | W18: Source Table 1
A19: MG-ZNA-018 | B19: Ni4Zr9Al1.5 | C19: Al10.3Ni27.6Zr62.1 | D19: Zr–Ni–Al | E19: Al–Ni–Zr | F19: 691 | G19: 739 | H19: 1176 | I19: 1239 | M19: Copper mold suction casting | N19: Rod | O19: SRC21 | P19: 10.1007/s11434-011-4842-z | Q19: Table 1, p.3906 | R19: VERIFIED_PRIMARY | S19: PASS | T19: NO | V19: PENDING | W19: Source Table 1
A20: MG-ZNA-019 | B20: Ni4Zr9Al2 | C20: Al13.3Ni26.7Zr60.0 | D20: Zr–Ni–Al | E20: Al–Ni–Zr | F20: 707 | G20: 775 | H20: 1179 | I20: 1222 | M20: Copper mold suction casting | N20: Rod | O20: SRC21 | P20: 10.1007/s11434-011-4842-z | Q20: Table 1, p.3906 | R20: VERIFIED_PRIMARY | S20: PASS | T20: NO | V20: PENDING | W20: Best GFA in source; abstract describes centimeter-scale BMG; exact dc not entered from prose.
A21: MG-ZNA-020 | B21: Ni4Zr9Al3 | C21: Al18.8Ni25.0Zr56.2 | D21: Zr–Ni–Al | E21: Al–Ni–Zr | F21: 742 | G21: 804 | H21: 1184 | I21: 1336 | M21: Copper mold suction casting | N21: Rod | O21: SRC21 | P21: 10.1007/s11434-011-4842-z | Q21: Table 1, p.3906 | R21: VERIFIED_PRIMARY | S21: PASS | T21: NO | V21: PENDING | W21: Source Table 1
A22: MG-ZNA-021 | B22: Ni3Zr6Al1 | C22: Al10.0Ni30.0Zr60.0 | D22: Zr–Ni–Al | E22: Al–Ni–Zr | F22: 702 | G22: 743 | H22: 1178 | I22: 1219 | M22: Copper mold suction casting | N22: Rod | O22: SRC21 | P22: 10.1007/s11434-011-4842-z | Q22: Table 1, p.3906 | R22: VERIFIED_PRIMARY | S22: PASS | T22: NO | V22: PENDING | W22: Source Table 1
A23: MG-ZNA-022 | B23: Ni3Zr6Al1.5 | C23: Al14.3Ni28.6Zr57.1 | D23: Zr–Ni–Al | E23: Al–Ni–Zr | F23: 720 | G23: 780 | H23: 1177 | I23: 1280 | M23: Copper mold suction casting | N23: Rod | O23: SRC21 | P23: 10.1007/s11434-011-4842-z | Q23: Table 1, p.3906 | R23: VERIFIED_PRIMARY | S23: PASS | T23: NO | V23: PENDING | W23: Source Table 1
A24: MG-ZNA-023 | B24: Ni3Zr6Al2 | C24: Al18.2Ni27.3Zr54.5 | D24: Zr–Ni–Al | E24: Al–Ni–Zr | F24: 748 | G24: 800 | H24: 1186 | I24: 1252 | M24: Copper mold suction casting | N24: Rod | O24: SRC21 | P24: 10.1007/s11434-011-4842-z | Q24: Table 1, p.3906 | R24: VERIFIED_PRIMARY | S24: PASS | T24: NO | V24: PENDING | W24: Source Table 1
A25: MG-ZNA-024 | B25: Ni3Zr6Al3 | C25: Al25.0Ni25.0Zr50.0 | D25: Zr–Ni–Al | E25: Al–Ni–Zr | F25: 659 | G25: 710 | H25: 1180 | I25: 1348 | M25: Copper mold suction casting | N25: Rod | O25: SRC21 | P25: 10.1007/s11434-011-4842-z | Q25: Table 1, p.3906 | R25: VERIFIED_PRIMARY | S25: PASS | T25: YES | U25: Composition_normalized corrected from erroneous Al25Ni25Zr60 to stoichiometric Ni3Zr6Al3 = Al25Ni25Zr50; raw formula retained. | V25: PENDING | W25: Composition correction is arithmetic from the published raw formula; thermal values remain source-transcribed.
A26: MG-ZNA-025 | B26: Reference | C26: Al15.0Ni25.0Zr60.0 | D26: Zr–Ni–Al | E26: Al–Ni–Zr | F26: 710 | G26: 778 | H26: 1177 | I26: 1251 | J26: 8 | M26: Copper mold suction casting | N26: Rod | O26: SRC21 | P26: 10.1007/s11434-011-4842-z | Q26: Table 1 p.3906 + Fig. critical-size caption | R26: VERIFIED_PRIMARY | S26: PASS | T26: NO | V26: PENDING | W26: Reference composition; source figure text states critical size 8 mm under present casting conditions.
A27: MG-CZA-001 | B27: Cu47Zr45Al8 | C27: Cu47Zr45Al8 | D27: Cu–Zr–Al | E27: Cu–Zr–Al | F27: 714 | G27: 794 | I27: 1190 | J27: 15 | M27: Not specified in extracted table | N27: Rod/BMG | O27: SRC33 | P27: 10.1590/1980-5373-MR-2019-0078 | Q27: Table 1 | R27: VERIFIED_PRIMARY | S27: PASS | T27: NO | V27: YES | W27: Open-access full article table.
A28: MG-CZA-002 | B28: (Cu47Zr45Al8)98.5Y1.5 | C28: (Cu47Zr45Al8)98.5Y1.5 | D28: Cu–Zr–Al | E28: Y-modified Cu–Zr–Al | F28: 698 | G28: 783 | I28: 1168 | J28: 25 | M28: Not specified in extracted table | N28: Rod/BMG | O28: SRC33 | P28: 10.1590/1980-5373-MR-2019-0078 | Q28: Table 1 | R28: VERIFIED_PRIMARY | S28: PASS | T28: NO | V28: YES | W28: Open-access full article table.
A29: MG-CZA-003 | B29: (Cu47Zr45Al8)99Nb | C29: (Cu47Zr45Al8)99Nb | D29: Cu–Zr–Al | E29: Nb-modified Cu–Zr–Al | F29: 717 | G29: 790 | I29: 1185 | J29: 12 | M29: Not specified in extracted table | N29: Rod/BMG | O29: SRC33 | P29: 10.1590/1980-5373-MR-2019-0078 | Q29: Table 1 | R29: VERIFIED_PRIMARY | S29: PASS | T29: NO | V29: YES | W29: Open-access full article table.
A30: MG-CZA-004 | B30: (Cu47Zr45Al8)97.5Y1.5Nb | C30: (Cu47Zr45Al8)97.5Y1.5Nb | D30: Cu–Zr–Al | E30: Y/Nb-modified Cu–Zr–Al | F30: 710 | G30: 793 | I30: 1161 | J30: 18 | M30: Not specified in extracted table | N30: Rod/BMG | O30: SRC33 | P30: 10.1590/1980-5373-MR-2019-0078 | Q30: Table 1 | R30: VERIFIED_PRIMARY | S30: PASS | T30: NO | V30: YES | W30: Open-access full article table.
A31: MG-MIX-001 | B31: Zr48Cu43Al7Ag2 | C31: Zr48Cu43Al7Ag2 | D31: Mixed BMG | E31: Zr-based | F31: 700 | G31: 761 | I31: 1152 | J31: 12 | M31: Compiled literature | N31: BMG | O31: SRC30 | P31: 10.1016/j.jallcom.2008.07.087 | Q31: Table 2 | R31: VERIFIED_COMPILATION | S31: PASS | T31: NO | U31: Primary reference [24] not yet audited | V31: NO | W31: Long et al. compilation; retain until primary ref audit.
A32: MG-MIX-002 | B32: Zr48Cu42Al7Ag3 | C32: Zr48Cu42Al7Ag3 | D32: Mixed BMG | E32: Zr-based | F32: 700 | G32: 763 | I32: 1135 | J32: 10 | M32: Compiled literature | N32: BMG | O32: SRC30 | P32: 10.1016/j.jallcom.2008.07.087 | Q32: Table 2 | R32: VERIFIED_COMPILATION | S32: PASS | T32: NO | U32: Primary reference [24] not yet audited | V32: NO | W32: Long et al. compilation.
A33: MG-MIX-003 | B33: Zr48Cu40Al7Ag5 | C33: Zr48Cu40Al7Ag5 | D33: Mixed BMG | E33: Zr-based | F33: 699 | G33: 769 | I33: 1121 | J33: 10 | M33: Compiled literature | N33: BMG | O33: SRC30 | P33: 10.1016/j.jallcom.2008.07.087 | Q33: Table 2 | R33: VERIFIED_COMPILATION | S33: PASS | T33: NO | U33: Primary reference [24] not yet audited | V33: NO | W33: Long et al. compilation.
A34: MG-MIX-004 | B34: Zr48Cu37Al7Ag8 | C34: Zr48Cu37Al7Ag8 | D34: Mixed BMG | E34: Zr-based | F34: 698 | G34: 765 | I34: 1125 | J34: 10 | M34: Compiled literature | N34: BMG | O34: SRC30 | P34: 10.1016/j.jallcom.2008.07.087 | Q34: Table 2 | R34: VERIFIED_COMPILATION | S34: PASS | T34: NO | U34: Primary reference [24] not yet audited | V34: NO | W34: Long et al. compilation.
A35: MG-MIX-005 | B35: Zr48Cu36Ag8Al8 | C35: Zr48Cu36Ag8Al8 | D35: Mixed BMG | E35: Zr-based | F35: 690 | G35: 791 | I35: 1143 | J35: 25 | M35: Compiled literature | N35: BMG | O35: SRC30 | P35: 10.1016/j.jallcom.2008.07.087 | Q35: Table 2 | R35: VERIFIED_COMPILATION | S35: PASS | T35: NO | U35: Primary reference [37] not yet audited | V35: NO | W35: Long et al. compilation.
A36: MG-MIX-006 | B36: Zr48Cu34Pd2Ag8Al8 | C36: Zr48Cu34Pd2Ag8Al8 | D36: Mixed BMG | E36: Zr-based | F36: 699 | G36: 794 | I36: 1140 | J36: 30 | M36: Compiled literature | N36: BMG | O36: SRC30 | P36: 10.1016/j.jallcom.2008.07.087 | Q36: Table 2 | R36: VERIFIED_COMPILATION | S36: PASS | T36: NO | U36: Primary reference [37] not yet audited | V36: NO | W36: Long et al. compilation.
A37: MG-MIX-007 | B37: Zr50Cu48Ag2 | C37: Zr50Cu48Ag2 | D37: Mixed BMG | E37: Zr-based | F37: 668 | G37: 719 | I37: 1192 | J37: 2 | M37: Compiled literature | N37: BMG | O37: SRC30 | P37: 10.1016/j.jallcom.2008.07.087 | Q37: Table 2 | R37: VERIFIED_COMPILATION | S37: PASS | T37: NO | U37: Primary reference [28] not yet audited | V37: NO | W37: Long et al. compilation.
A38: MG-MIX-008 | B38: Zr50Cu45Ag5 | C38: Zr50Cu45Ag5 | D38: Mixed BMG | E38: Zr-based | F38: 669 | G38: 728 | I38: 1188 | J38: 4 | M38: Compiled literature | N38: BMG | O38: SRC30 | P38: 10.1016/j.jallcom.2008.07.087 | Q38: Table 2 | R38: VERIFIED_COMPILATION | S38: PASS | T38: NO | U38: Primary reference [28] not yet audited | V38: NO | W38: Long et al. compilation.
A39: MG-MIX-009 | B39: Zr50Cu43Ag7 | C39: Zr50Cu43Ag7 | D39: Mixed BMG | E39: Zr-based | F39: 669 | G39: 727 | I39: 1171 | J39: 4 | M39: Compiled literature | N39: BMG | O39: SRC30 | P39: 10.1016/j.jallcom.2008.07.087 | Q39: Table 2 | R39: VERIFIED_COMPILATION | S39: PASS | T39: NO | U39: Primary reference [28] not yet audited | V39: NO | W39: Long et al. compilation.
A40: MG-MIX-010 | B40: Zr50Cu40Ag10 | C40: Zr50Cu40Ag10 | D40: Mixed BMG | E40: Zr-based | F40: 667 | G40: 733 | I40: 1177 | J40: 5 | M40: Compiled literature | N40: BMG | O40: SRC30 | P40: 10.1016/j.jallcom.2008.07.087 | Q40: Table 2 | R40: VERIFIED_COMPILATION | S40: PASS | T40: NO | U40: Primary reference [28] not yet audited | V40: NO | W40: Long et al. compilation.
...

Sheet Derived_Descriptors
A1: MG_ID | B1: Tg_K | C1: Tx_K | D1: Tm_K | E1: Tl_K | F1: DeltaTx_K | G1: Trg_Tg_Tl | H1: Trg_Tg_Tm | I1: Gamma | J1: Gamma_m | K1: DeltaTrg | L1: Delta_param | M1: Phi | N1: Alpha | O1: Beta_sum | P1: Omega | Q1: Source_reported_DeltaTx | R1: Source_reported_Trg | S1: Source_reported_Gamma | T1: Descriptor_QC
A2: =Master_Database!A2 -> MG-ZNA-001 | B2: =Master_Database!F2 -> 663 | C2: =Master_Database!G2 -> 710 | D2: =Master_Database!H2 -> 1199 | E2: =Master_Database!I2 -> 1236 | F2: =IF(OR(B2="",C2=""),"",C2-B2) -> 47 | G2: =IF(OR(B2="",E2=""),"",B2/E2) -> 0.53640777 | H2: =IF(OR(B2="",D2=""),"",B2/D2) -> 0.5529608 | I2: =IF(OR(B2="",C2="",E2=""),"",C2/(B2+E2)) -> 0.37388099 | J2: =IF(OR(B2="",C2="",E2=""),"",(2*C2-B2)/E2) -> 0.61245955 | K2: =IF(OR(B2="",C2="",E2=""),"",(C2-B2)/(E2-B2)) -> 0.082024433 | L2: =IF(OR(B2="",C2="",E2=""),"",C2/(E2-B2)) -> 1.2390925 | M2: =IF(OR(B2="",C2="",E2=""),"",(B2/E2)*((C2-B2)/B2)^0.143) -> 0.36739109 | N2: =IF(OR(C2="",E2=""),"",C2/E2) -> 0.57443366 | O2: =IF(OR(B2="",C2="",E2=""),"",C2/B2+B2/E2) -> 1.6072977 | P2: =IF(OR(B2="",C2="",E2=""),"",B2/C2-2*B2/(B2+E2)) -> 0.23554057 | Q2: 38 | R2: 0.522 | S2: 0.584 | T2: PASS
A3: =Master_Database!A3 -> MG-ZNA-002 | B3: =Master_Database!F3 -> 682 | C3: =Master_Database!G3 -> 729 | D3: =Master_Database!H3 -> 1174 | E3: =Master_Database!I3 -> 1283 | F3: =IF(OR(B3="",C3=""),"",C3-B3) -> 47 | G3: =IF(OR(B3="",E3=""),"",B3/E3) -> 0.53156664 | H3: =IF(OR(B3="",D3=""),"",B3/D3) -> 0.58091993 | I3: =IF(OR(B3="",C3="",E3=""),"",C3/(B3+E3)) -> 0.37099237 | J3: =IF(OR(B3="",C3="",E3=""),"",(2*C3-B3)/E3) -> 0.60483242 | K3: =IF(OR(B3="",C3="",E3=""),"",(C3-B3)/(E3-B3)) -> 0.078202995 | L3: =IF(OR(B3="",C3="",E3=""),"",C3/(E3-B3)) -> 1.2129784 | M3: =IF(OR(B3="",C3="",E3=""),"",(B3/E3)*((C3-B3)/B3)^0.143) -> 0.3626073 | N3: =IF(OR(C3="",E3=""),"",C3/E3) -> 0.56819953 | O3: =IF(OR(B3="",C3="",E3=""),"",C3/B3+B3/E3) -> 1.6004816 | P3: =IF(OR(B3="",C3="",E3=""),"",B3/C3-2*B3/(B3+E3)) -> 0.24138054 | Q3: 45 | R3: 0.522 | S3: 0.593 | T3: PASS
A4: =Master_Database!A4 -> MG-ZNA-003 | B4: =Master_Database!F4 -> 703 | C4: =Master_Database!G4 -> 758 | D4: =Master_Database!H4 -> 1178 | E4: =Master_Database!I4 -> 1266 | F4: =IF(OR(B4="",C4=""),"",C4-B4) -> 55 | G4: =IF(OR(B4="",E4=""),"",B4/E4) -> 0.55529226 | H4: =IF(OR(B4="",D4=""),"",B4/D4) -> 0.59677419 | I4: =IF(OR(B4="",C4="",E4=""),"",C4/(B4+E4)) -> 0.38496699 | J4: =IF(OR(B4="",C4="",E4=""),"",(2*C4-B4)/E4) -> 0.64218009 | K4: =IF(OR(B4="",C4="",E4=""),"",(C4-B4)/(E4-B4)) -> 0.097690941 | L4: =IF(OR(B4="",C4="",E4=""),"",C4/(E4-B4)) -> 1.3463588 | M4: =IF(OR(B4="",C4="",E4=""),"",(B4/E4)*((C4-B4)/B4)^0.143) -> 0.38572596 | N4: =IF(OR(C4="",E4=""),"",C4/E4) -> 0.59873618 | O4: =IF(OR(B4="",C4="",E4=""),"",C4/B4+B4/E4) -> 1.6335284 | P4: =IF(OR(B4="",C4="",E4=""),"",B4/C4-2*B4/(B4+E4)) -> 0.21337258 | Q4: 43 | R4: 0.515 | S4: 0.581 | T4: PASS
A5: =Master_Database!A5 -> MG-ZNA-004 | B5: =Master_Database!F5 -> 745 | C5: =Master_Database!G5 -> 784 | D5: =Master_Database!H5 -> 1183 | E5: =Master_Database!I5 -> 1342 | F5: =IF(OR(B5="",C5=""),"",C5-B5) -> 39 | G5: =IF(OR(B5="",E5=""),"",B5/E5) -> 0.55514158 | H5: =IF(OR(B5="",D5=""),"",B5/D5) -> 0.62975486 | I5: =IF(OR(B5="",C5="",E5=""),"",C5/(B5+E5)) -> 0.37565884 | J5: =IF(OR(B5="",C5="",E5=""),"",(2*C5-B5)/E5) -> 0.61326379 | K5: =IF(OR(B5="",C5="",E5=""),"",(C5-B5)/(E5-B5)) -> 0.065326633 | L5: =IF(OR(B5="",C5="",E5=""),"",C5/(E5-B5)) -> 1.3132328 | M5: =IF(OR(B5="",C5="",E5=""),"",(B5/E5)*((C5-B5)/B5)^0.143) -> 0.36408908 | N5: =IF(OR(C5="",E5=""),"",C5/E5) -> 0.58420268 | O5: =IF(OR(B5="",C5="",E5=""),"",C5/B5+B5/E5) -> 1.6074906 | P5: =IF(OR(B5="",C5="",E5=""),"",B5/C5-2*B5/(B5+E5)) -> 0.23631164 | Q5: 39 | R5: 0.54 | S5: 0.599 | T5: PASS
A6: =Master_Database!A6 -> MG-ZNA-005 | B6: =Master_Database!F6 -> 680 | C6: =Master_Database!G6 -> 721 | D6: =Master_Database!H6 -> 1178 | E6: =Master_Database!I6 -> 1220 | F6: =IF(OR(B6="",C6=""),"",C6-B6) -> 41 | G6: =IF(OR(B6="",E6=""),"",B6/E6) -> 0.55737705 | H6: =IF(OR(B6="",D6=""),"",B6/D6) -> 0.57724958 | I6: =IF(OR(B6="",C6="",E6=""),"",C6/(B6+E6)) -> 0.37947368 | J6: =IF(OR(B6="",C6="",E6=""),"",(2*C6-B6)/E6) -> 0.62459016 | K6: =IF(OR(B6="",C6="",E6=""),"",(C6-B6)/(E6-B6)) -> 0.075925926 | L6: =IF(OR(B6="",C6="",E6=""),"",C6/(E6-B6)) -> 1.3351852 | M6: =IF(OR(B6="",C6="",E6=""),"",(B6/E6)*((C6-B6)/B6)^0.143) -> 0.37301681 | N6: =IF(OR(C6="",E6=""),"",C6/E6) -> 0.59098361 | O6: =IF(OR(B6="",C6="",E6=""),"",C6/B6+B6/E6) -> 1.6176712 | P6: =IF(OR(B6="",C6="",E6=""),"",B6/C6-2*B6/(B6+E6)) -> 0.22734506 | Q6: 42 | R6: 0.526 | S6: 0.594 | T6: PASS
A7: =Master_Database!A7 -> MG-ZNA-006 | B7: =Master_Database!F7 -> 702 | C7: =Master_Database!G7 -> 770 | D7: =Master_Database!H7 -> 1176 | E7: =Master_Database!I7 -> 1263 | F7: =IF(OR(B7="",C7=""),"",C7-B7) -> 68 | G7: =IF(OR(B7="",E7=""),"",B7/E7) -> 0.55581948 | H7: =IF(OR(B7="",D7=""),"",B7/D7) -> 0.59693878 | I7: =IF(OR(B7="",C7="",E7=""),"",C7/(B7+E7)) -> 0.39185751 | J7: =IF(OR(B7="",C7="",E7=""),"",(2*C7-B7)/E7) -> 0.6634996 | K7: =IF(OR(B7="",C7="",E7=""),"",(C7-B7)/(E7-B7)) -> 0.12121212 | L7: =IF(OR(B7="",C7="",E7=""),"",C7/(E7-B7)) -> 1.372549 | M7: =IF(OR(B7="",C7="",E7=""),"",(B7/E7)*((C7-B7)/B7)^0.143) -> 0.39806714 | N7: =IF(OR(C7="",E7=""),"",C7/E7) -> 0.60965954 | O7: =IF(OR(B7="",C7="",E7=""),"",C7/B7+B7/E7) -> 1.6526856 | P7: =IF(OR(B7="",C7="",E7=""),"",B7/C7-2*B7/(B7+E7)) -> 0.19718449 | Q7: 48 | R7: 0.523 | S7: 0.599 | T7: PASS
A8: =Master_Database!A8 -> MG-ZNA-007 | B8: =Master_Database!F8 -> 721 | C8: =Master_Database!G8 -> 789 | D8: =Master_Database!H8 -> 1185 | E8: =Master_Database!I8 -> 1289 | F8: =IF(OR(B8="",C8=""),"",C8-B8) -> 68 | G8: =IF(OR(B8="",E8=""),"",B8/E8) -> 0.55934833 | H8: =IF(OR(B8="",D8=""),"",B8/D8) -> 0.60843882 | I8: =IF(OR(B8="",C8="",E8=""),"",C8/(B8+E8)) -> 0.39253731 | J8: =IF(OR(B8="",C8="",E8=""),"",(2*C8-B8)/E8) -> 0.66485648 | K8: =IF(OR(B8="",C8="",E8=""),"",(C8-B8)/(E8-B8)) -> 0.11971831 | L8: =IF(OR(B8="",C8="",E8=""),"",C8/(E8-B8)) -> 1.3890845 | M8: =IF(OR(B8="",C8="",E8=""),"",(B8/E8)*((C8-B8)/B8)^0.143) -> 0.39906752 | N8: =IF(OR(C8="",E8=""),"",C8/E8) -> 0.6121024 | O8: =IF(OR(B8="",C8="",E8=""),"",C8/B8+B8/E8) -> 1.6536618 | P8: =IF(OR(B8="",C8="",E8=""),"",B8/C8-2*B8/(B8+E8)) -> 0.19640202 | Q8: 41 | R8: 0.524 | S8: 0.587 | T8: PASS
A9: =Master_Database!A9 -> MG-ZNA-008 | B9: =Master_Database!F9 -> 772 | C9: =Master_Database!G9 -> 813 | D9: =Master_Database!H9 -> 1182 | E9: =Master_Database!I9 -> 1338 | F9: =IF(OR(B9="",C9=""),"",C9-B9) -> 41 | G9: =IF(OR(B9="",E9=""),"",B9/E9) -> 0.57698057 | H9: =IF(OR(B9="",D9=""),"",B9/D9) -> 0.65313029 | I9: =IF(OR(B9="",C9="",E9=""),"",C9/(B9+E9)) -> 0.38530806 | J9: =IF(OR(B9="",C9="",E9=""),"",(2*C9-B9)/E9) -> 0.63826607 | K9: =IF(OR(B9="",C9="",E9=""),"",(C9-B9)/(E9-B9)) -> 0.072438163 | L9: =IF(OR(B9="",C9="",E9=""),"",C9/(E9-B9)) -> 1.4363958 | M9: =IF(OR(B9="",C9="",E9=""),"",(B9/E9)*((C9-B9)/B9)^0.143) -> 0.37919273 | N9: =IF(OR(C9="",E9=""),"",C9/E9) -> 0.60762332 | O9: =IF(OR(B9="",C9="",E9=""),"",C9/B9+B9/E9) -> 1.6300894 | P9: =IF(OR(B9="",C9="",E9=""),"",B9/C9-2*B9/(B9+E9)) -> 0.21781594 | Q9: 38 | R9: 0.542 | S9: 0.598 | T9: PASS
A10: =Master_Database!A10 -> MG-ZNA-009 | B10: =Master_Database!F10 -> 673 | C10: =Master_Database!G10 -> 706 | D10: =Master_Database!H10 -> 1178 | E10: =Master_Database!I10 -> 1244 | F10: =IF(OR(B10="",C10=""),"",C10-B10) -> 33 | G10: =IF(OR(B10="",E10=""),"",B10/E10) -> 0.54099678 | H10: =IF(OR(B10="",D10=""),"",B10/D10) -> 0.5713073 | I10: =IF(OR(B10="",C10="",E10=""),"",C10/(B10+E10)) -> 0.36828378 | J10: =IF(OR(B10="",C10="",E10=""),"",(2*C10-B10)/E10) -> 0.59405145 | K10: =IF(OR(B10="",C10="",E10=""),"",(C10-B10)/(E10-B10)) -> 0.057793345 | L10: =IF(OR(B10="",C10="",E10=""),"",C10/(E10-B10)) -> 1.2364273 | M10: =IF(OR(B10="",C10="",E10=""),"",(B10/E10)*((C10-B10)/B10)^0.143) -> 0.35150866 | N10: =IF(OR(C10="",E10=""),"",C10/E10) -> 0.56752412 | O10: =IF(OR(B10="",C10="",E10=""),"",C10/B10+B10/E10) -> 1.590031 | P10: =IF(OR(B10="",C10="",E10=""),"",B10/C10-2*B10/(B10+E10)) -> 0.25111903 | Q10: 47 | R10: 0.536 | S10: 0.612 | T10: PASS
A11: =Master_Database!A11 -> MG-ZNA-010 | B11: =Master_Database!F11 -> 691 | C11: =Master_Database!G11 -> 739 | D11: =Master_Database!H11 -> 1176 | E11: =Master_Database!I11 -> 1239 | F11: =IF(OR(B11="",C11=""),"",C11-B11) -> 48 | G11: =IF(OR(B11="",E11=""),"",B11/E11) -> 0.55770783 | H11: =IF(OR(B11="",D11=""),"",B11/D11) -> 0.58758503 | I11: =IF(OR(B11="",C11="",E11=""),"",C11/(B11+E11)) -> 0.38290155 | J11: =IF(OR(B11="",C11="",E11=""),"",(2*C11-B11)/E11) -> 0.63518967 | K11: =IF(OR(B11="",C11="",E11=""),"",(C11-B11)/(E11-B11)) -> 0.087591241 | L11: =IF(OR(B11="",C11="",E11=""),"",C11/(E11-B11)) -> 1.3485401 | M11: =IF(OR(B11="",C11="",E11=""),"",(B11/E11)*((C11-B11)/B11)^0.143) -> 0.38087185 | N11: =IF(OR(C11="",E11=""),"",C11/E11) -> 0.59644875 | O11: =IF(OR(B11="",C11="",E11=""),"",C11/B11+B11/E11) -> 1.6271724 | P11: =IF(OR(B11="",C11="",E11=""),"",B11/C11-2*B11/(B11+E11)) -> 0.21898519 | Q11: 47 | R11: 0.532 | S11: 0.605 | T11: PASS
A12: =Master_Database!A12 -> MG-ZNA-011 | B12: =Master_Database!F12 -> 707 | C12: =Master_Database!G12 -> 775 | D12: =Master_Database!H12 -> 1179 | E12: =Master_Database!I12 -> 1222 | F12: =IF(OR(B12="",C12=""),"",C12-B12) -> 68 | G12: =IF(OR(B12="",E12=""),"",B12/E12) -> 0.57855974 | H12: =IF(OR(B12="",D12=""),"",B12/D12) -> 0.59966073 | I12: =IF(OR(B12="",C12="",E12=""),"",C12/(B12+E12)) -> 0.40176257 | J12: =IF(OR(B12="",C12="",E12=""),"",(2*C12-B12)/E12) -> 0.6898527 | K12: =IF(OR(B12="",C12="",E12=""),"",(C12-B12)/(E12-B12)) -> 0.13203883 | L12: =IF(OR(B12="",C12="",E12=""),"",C12/(E12-B12)) -> 1.5048544 | M12: =IF(OR(B12="",C12="",E12=""),"",(B12/E12)*((C12-B12)/B12)^0.143) -> 0.41393296 | N12: =IF(OR(C12="",E12=""),"",C12/E12) -> 0.63420622 | O12: =IF(OR(B12="",C12="",E12=""),"",C12/B12+B12/E12) -> 1.6747408 | P12: =IF(OR(B12="",C12="",E12=""),"",B12/C12-2*B12/(B12+E12)) -> 0.17923577 | Q12: 55 | R12: 0.555 | S12: 0.642 | T12: PASS
A13: =Master_Database!A13 -> MG-ZNA-012 | B13: =Master_Database!F13 -> 742 | C13: =Master_Database!G13 -> 804 | D13: =Master_Database!H13 -> 1184 | E13: =Master_Database!I13 -> 1336 | F13: =IF(OR(B13="",C13=""),"",C13-B13) -> 62 | G13: =IF(OR(B13="",E13=""),"",B13/E13) -> 0.55538922 | H13: =IF(OR(B13="",D13=""),"",B13/D13) -> 0.62668919 | I13: =IF(OR(B13="",C13="",E13=""),"",C13/(B13+E13)) -> 0.38691049 | J13: =IF(OR(B13="",C13="",E13=""),"",(2*C13-B13)/E13) -> 0.64820359 | K13: =IF(OR(B13="",C13="",E13=""),"",(C13-B13)/(E13-B13)) -> 0.1043771 | L13: =IF(OR(B13="",C13="",E13=""),"",C13/(E13-B13)) -> 1.3535354 | M13: =IF(OR(B13="",C13="",E13=""),"",(B13/E13)*((C13-B13)/B13)^0.143) -> 0.38944103 | N13: =IF(OR(C13="",E13=""),"",C13/E13) -> 0.60179641 | O13: =IF(OR(B13="",C13="",E13=""),"",C13/B13+B13/E13) -> 1.6389472 | P13: =IF(OR(B13="",C13="",E13=""),"",B13/C13-2*B13/(B13+E13)) -> 0.20873735 | Q13: 39 | R13: 0.557 | S13: 0.615 | T13: PASS
... A26: =Master_Database!A26 -> MG-ZNA-025 | B26: =Master_Database!F26 -> 710 | C26: =Master_Database!G26 -> 778 | D26: =Master_Database!H26 -> 1177 | E26: =Master_Database!I26 -> 1251 | F26: =IF(OR(B26="",C26=""),"",C26-B26) -> 68 | G26: =IF(OR(B26="",E26=""),"",B26/E26) -> 0.56754596 | H26: =IF(OR(B26="",D26=""),"",B26/D26) -> 0.60322855 | I26: =IF(OR(B26="",C26="",E26=""),"",C26/(B26+E26)) -> 0.39673636 | J26: =IF(OR(B26="",C26="",E26=""),"",(2*C26-B26)/E26) -> 0.67625899 | K26: =IF(OR(B26="",C26="",E26=""),"",(C26-B26)/(E26-B26)) -> 0.12569316 | L26: =IF(OR(B26="",C26="",E26=""),"",C26/(E26-B26)) -> 1.4380776 | M26: =IF(OR(B26="",C26="",E26=""),"",(B26/E26)*((C26-B26)/B26)^0.143) -> 0.40580731 | N26: =IF(OR(C26="",E26=""),"",C26/E26) -> 0.62190248 | O26: =IF(OR(B26="",C26="",E26=""),"",C26/B26+B26/E26) -> 1.6633206 | P26: =IF(OR(B26="",C26="",E26=""),"",B26/C26-2*B26/(B26+E26)) -> 0.18847605 | Q26: 68 | R26: 0.568 | S26: 0.676 | T26: PASS
A27: =Master_Database!A27 -> MG-CZA-001 | B27: =Master_Database!F27 -> 714 | C27: =Master_Database!G27 -> 794 | D27: =Master_Database!H27 -> 0 | E27: =Master_Database!I27 -> 1190 | F27: =IF(OR(B27="",C27=""),"",C27-B27) -> 80 | G27: =IF(OR(B27="",E27=""),"",B27/E27) -> 0.6 | H27: =IF(OR(B27="",D27=""),"",B27/D27) | I27: =IF(OR(B27="",C27="",E27=""),"",C27/(B27+E27)) -> 0.41701681 | J27: =IF(OR(B27="",C27="",E27=""),"",(2*C27-B27)/E27) -> 0.73445378 | K27: =IF(OR(B27="",C27="",E27=""),"",(C27-B27)/(E27-B27)) -> 0.16806723 | L27: =IF(OR(B27="",C27="",E27=""),"",C27/(E27-B27)) -> 1.6680672 | M27: =IF(OR(B27="",C27="",E27=""),"",(B27/E27)*((C27-B27)/B27)^0.143) -> 0.43874712 | N27: =IF(OR(C27="",E27=""),"",C27/E27) -> 0.66722689 | O27: =IF(OR(B27="",C27="",E27=""),"",C27/B27+B27/E27) -> 1.7120448 | P27: =IF(OR(B27="",C27="",E27=""),"",B27/C27-2*B27/(B27+E27)) -> 0.14924433 | T27: PASS
A28: =Master_Database!A28 -> MG-CZA-002 | B28: =Master_Database!F28 -> 698 | C28: =Master_Database!G28 -> 783 | D28: =Master_Database!H28 -> 0 | E28: =Master_Database!I28 -> 1168 | F28: =IF(OR(B28="",C28=""),"",C28-B28) -> 85 | G28: =IF(OR(B28="",E28=""),"",B28/E28) -> 0.59760274 | H28: =IF(OR(B28="",D28=""),"",B28/D28) | I28: =IF(OR(B28="",C28="",E28=""),"",C28/(B28+E28)) -> 0.41961415 | J28: =IF(OR(B28="",C28="",E28=""),"",(2*C28-B28)/E28) -> 0.74315068 | K28: =IF(OR(B28="",C28="",E28=""),"",(C28-B28)/(E28-B28)) -> 0.18085106 | L28: =IF(OR(B28="",C28="",E28=""),"",C28/(E28-B28)) -> 1.6659574 | M28: =IF(OR(B28="",C28="",E28=""),"",(B28/E28)*((C28-B28)/B28)^0.143) -> 0.44222996 | N28: =IF(OR(C28="",E28=""),"",C28/E28) -> 0.67037671 | O28: =IF(OR(B28="",C28="",E28=""),"",C28/B28+B28/E28) -> 1.7193792 | P28: =IF(OR(B28="",C28="",E28=""),"",B28/C28-2*B28/(B28+E28)) -> 0.14331884 | T28: PASS
A29: =Master_Database!A29 -> MG-CZA-003 | B29: =Master_Database!F29 -> 717 | C29: =Master_Database!G29 -> 790 | D29: =Master_Database!H29 -> 0 | E29: =Master_Database!I29 -> 1185 | F29: =IF(OR(B29="",C29=""),"",C29-B29) -> 73 | G29: =IF(OR(B29="",E29=""),"",B29/E29) -> 0.60506329 | H29: =IF(OR(B29="",D29=""),"",B29/D29) | I29: =IF(OR(B29="",C29="",E29=""),"",C29/(B29+E29)) -> 0.41535226 | J29: =IF(OR(B29="",C29="",E29=""),"",(2*C29-B29)/E29) -> 0.72827004 | K29: =IF(OR(B29="",C29="",E29=""),"",(C29-B29)/(E29-B29)) -> 0.15598291 | L29: =IF(OR(B29="",C29="",E29=""),"",C29/(E29-B29)) -> 1.6880342 | M29: =IF(OR(B29="",C29="",E29=""),"",(B29/E29)*((C29-B29)/B29)^0.143) -> 0.43643215 | N29: =IF(OR(C29="",E29=""),"",C29/E29) -> 0.66666667 | O29: =IF(OR(B29="",C29="",E29=""),"",C29/B29+B29/E29) -> 1.7068764 | P29: =IF(OR(B29="",C29="",E29=""),"",B29/C29-2*B29/(B29+E29)) -> 0.15365172 | T29: PASS
A30: =Master_Database!A30 -> MG-CZA-004 | B30: =Master_Database!F30 -> 710 | C30: =Master_Database!G30 -> 793 | D30: =Master_Database!H30 -> 0 | E30: =Master_Database!I30 -> 1161 | F30: =IF(OR(B30="",C30=""),"",C30-B30) -> 83 | G30: =IF(OR(B30="",E30=""),"",B30/E30) -> 0.61154177 | H30: =IF(OR(B30="",D30=""),"",B30/D30) | I30: =IF(OR(B30="",C30="",E30=""),"",C30/(B30+E30)) -> 0.42383752 | J30: =IF(OR(B30="",C30="",E30=""),"",(2*C30-B30)/E30) -> 0.75452196 | K30: =IF(OR(B30="",C30="",E30=""),"",(C30-B30)/(E30-B30)) -> 0.18403548 | L30: =IF(OR(B30="",C30="",E30=""),"",C30/(E30-B30)) -> 1.7583149 | M30: =IF(OR(B30="",C30="",E30=""),"",(B30/E30)*((C30-B30)/B30)^0.143) -> 0.44990866 | N30: =IF(OR(C30="",E30=""),"",C30/E30) -> 0.68303187 | O30: =IF(OR(B30="",C30="",E30=""),"",C30/B30+B30/E30) -> 1.7284432 | P30: =IF(OR(B30="",C30="",E30=""),"",B30/C30-2*B30/(B30+E30)) -> 0.13638174 | T30: PASS
A31: =Master_Database!A31 -> MG-MIX-001 | B31: =Master_Database!F31 -> 700 | C31: =Master_Database!G31 -> 761 | D31: =Master_Database!H31 -> 0 | E31: =Master_Database!I31 -> 1152 | F31: =IF(OR(B31="",C31=""),"",C31-B31) -> 61 | G31: =IF(OR(B31="",E31=""),"",B31/E31) -> 0.60763889 | H31: =IF(OR(B31="",D31=""),"",B31/D31) | I31: =IF(OR(B31="",C31="",E31=""),"",C31/(B31+E31)) -> 0.41090713 | J31: =IF(OR(B31="",C31="",E31=""),"",(2*C31-B31)/E31) -> 0.71354167 | K31: =IF(OR(B31="",C31="",E31=""),"",(C31-B31)/(E31-B31)) -> 0.13495575 | L31: =IF(OR(B31="",C31="",E31=""),"",C31/(E31-B31)) -> 1.6836283 | M31: =IF(OR(B31="",C31="",E31=""),"",(B31/E31)*((C31-B31)/B31)^0.143) -> 0.42864593 | N31: =IF(OR(C31="",E31=""),"",C31/E31) -> 0.66059028 | O31: =IF(OR(B31="",C31="",E31=""),"",C31/B31+B31/E31) -> 1.6947817 | P31: =IF(OR(B31="",C31="",E31=""),"",B31/C31-2*B31/(B31+E31)) -> 0.16390279 | T31: PASS
A32: =Master_Database!A32 -> MG-MIX-002 | B32: =Master_Database!F32 -> 700 | C32: =Master_Database!G32 -> 763 | D32: =Master_Database!H32 -> 0 | E32: =Master_Database!I32 -> 1135 | F32: =IF(OR(B32="",C32=""),"",C32-B32) -> 63 | G32: =IF(OR(B32="",E32=""),"",B32/E32) -> 0.61674009 | H32: =IF(OR(B32="",D32=""),"",B32/D32) | I32: =IF(OR(B32="",C32="",E32=""),"",C32/(B32+E32)) -> 0.41580381 | J32: =IF(OR(B32="",C32="",E32=""),"",(2*C32-B32)/E32) -> 0.7277533 | K32: =IF(OR(B32="",C32="",E32=""),"",(C32-B32)/(E32-B32)) -> 0.14482759 | L32: =IF(OR(B32="",C32="",E32=""),"",C32/(E32-B32)) -> 1.754023 | M32: =IF(OR(B32="",C32="",E32=""),"",(B32/E32)*((C32-B32)/B32)^0.143) -> 0.43707791 | N32: =IF(OR(C32="",E32=""),"",C32/E32) -> 0.6722467 | O32: =IF(OR(B32="",C32="",E32=""),"",C32/B32+B32/E32) -> 1.7067401 | P32: =IF(OR(B32="",C32="",E32=""),"",B32/C32-2*B32/(B32+E32)) -> 0.15448841 | T32: PASS
A33: =Master_Database!A33 -> MG-MIX-003 | B33: =Master_Database!F33 -> 699 | C33: =Master_Database!G33 -> 769 | D33: =Master_Database!H33 -> 0 | E33: =Master_Database!I33 -> 1121 | F33: =IF(OR(B33="",C33=""),"",C33-B33) -> 70 | G33: =IF(OR(B33="",E33=""),"",B33/E33) -> 0.6235504 | H33: =IF(OR(B33="",D33=""),"",B33/D33) | I33: =IF(OR(B33="",C33="",E33=""),"",C33/(B33+E33)) -> 0.42252747 | J33: =IF(OR(B33="",C33="",E33=""),"",(2*C33-B33)/E33) -> 0.74843889 | K33: =IF(OR(B33="",C33="",E33=""),"",(C33-B33)/(E33-B33)) -> 0.16587678 | L33: =IF(OR(B33="",C33="",E33=""),"",C33/(E33-B33)) -> 1.8222749 | M33: =IF(OR(B33="",C33="",E33=""),"",(B33/E33)*((C33-B33)/B33)^0.143) -> 0.44870442 | N33: =IF(OR(C33="",E33=""),"",C33/E33) -> 0.68599465 | O33: =IF(OR(B33="",C33="",E33=""),"",C33/B33+B33/E33) -> 1.7236935 | P33: =IF(OR(B33="",C33="",E33=""),"",B33/C33-2*B33/(B33+E33)) -> 0.14084082 | T33: PASS
A34: =Master_Database!A34 -> MG-MIX-004 | B34: =Master_Database!F34 -> 698 | C34: =Master_Database!G34 -> 765 | D34: =Master_Database!H34 -> 0 | E34: =Master_Database!I34 -> 1125 | F34: =IF(OR(B34="",C34=""),"",C34-B34) -> 67 | G34: =IF(OR(B34="",E34=""),"",B34/E34) -> 0.62044444 | H34: =IF(OR(B34="",D34=""),"",B34/D34) | I34: =IF(OR(B34="",C34="",E34=""),"",C34/(B34+E34)) -> 0.41963796 | J34: =IF(OR(B34="",C34="",E34=""),"",(2*C34-B34)/E34) -> 0.73955556 | K34: =IF(OR(B34="",C34="",E34=""),"",(C34-B34)/(E34-B34)) -> 0.15690867 | L34: =IF(OR(B34="",C34="",E34=""),"",C34/(E34-B34)) -> 1.7915691 | M34: =IF(OR(B34="",C34="",E34=""),"",(B34/E34)*((C34-B34)/B34)^0.143) -> 0.44377238 | N34: =IF(OR(C34="",E34=""),"",C34/E34) -> 0.68 | O34: =IF(OR(B34="",C34="",E34=""),"",C34/B34+B34/E34) -> 1.716433 | P34: =IF(OR(B34="",C34="",E34=""),"",B34/C34-2*B34/(B34+E34)) -> 0.14664759 | T34: PASS
A35: =Master_Database!A35 -> MG-MIX-005 | B35: =Master_Database!F35 -> 690 | C35: =Master_Database!G35 -> 791 | D35: =Master_Database!H35 -> 0 | E35: =Master_Database!I35 -> 1143 | F35: =IF(OR(B35="",C35=""),"",C35-B35) -> 101 | G35: =IF(OR(B35="",E35=""),"",B35/E35) -> 0.60367454 | H35: =IF(OR(B35="",D35=""),"",B35/D35) | I35: =IF(OR(B35="",C35="",E35=""),"",C35/(B35+E35)) -> 0.43153301 | J35: =IF(OR(B35="",C35="",E35=""),"",(2*C35-B35)/E35) -> 0.78040245 | K35: =IF(OR(B35="",C35="",E35=""),"",(C35-B35)/(E35-B35)) -> 0.22295806 | L35: =IF(OR(B35="",C35="",E35=""),"",C35/(E35-B35)) -> 1.7461369 | M35: =IF(OR(B35="",C35="",E35=""),"",(B35/E35)*((C35-B35)/B35)^0.143) -> 0.4586331 | N35: =IF(OR(C35="",E35=""),"",C35/E35) -> 0.6920385 | O35: =IF(OR(B35="",C35="",E35=""),"",C35/B35+B35/E35) -> 1.7500514 | P35: =IF(OR(B35="",C35="",E35=""),"",B35/C35-2*B35/(B35+E35)) -> 0.11944937 | T35: PASS
A36: =Master_Database!A36 -> MG-MIX-006 | B36: =Master_Database!F36 -> 699 | C36: =Master_Database!G36 -> 794 | D36: =Master_Database!H36 -> 0 | E36: =Master_Database!I36 -> 1140 | F36: =IF(OR(B36="",C36=""),"",C36-B36) -> 95 | G36: =IF(OR(B36="",E36=""),"",B36/E36) -> 0.61315789 | H36: =IF(OR(B36="",D36=""),"",B36/D36) | I36: =IF(OR(B36="",C36="",E36=""),"",C36/(B36+E36)) -> 0.43175639 | J36: =IF(OR(B36="",C36="",E36=""),"",(2*C36-B36)/E36) -> 0.77982456 | K36: =IF(OR(B36="",C36="",E36=""),"",(C36-B36)/(E36-B36)) -> 0.2154195 | L36: =IF(OR(B36="",C36="",E36=""),"",C36/(E36-B36)) -> 1.8004535 | M36: =IF(OR(B36="",C36="",E36=""),"",(B36/E36)*((C36-B36)/B36)^0.143) -> 0.46092107 | N36: =IF(OR(C36="",E36=""),"",C36/E36) -> 0.69649123 | O36: =IF(OR(B36="",C36="",E36=""),"",C36/B36+B36/E36) -> 1.7490663 | P36: =IF(OR(B36="",C36="",E36=""),"",B36/C36-2*B36/(B36+E36)) -> 0.12015689 | T36: PASS
A37: =Master_Database!A37 -> MG-MIX-007 | B37: =Master_Database!F37 -> 668 | C37: =Master_Database!G37 -> 719 | D37: =Master_Database!H37 -> 0 | E37: =Master_Database!I37 -> 1192 | F37: =IF(OR(B37="",C37=""),"",C37-B37) -> 51 | G37: =IF(OR(B37="",E37=""),"",B37/E37) -> 0.56040268 | H37: =IF(OR(B37="",D37=""),"",B37/D37) | I37: =IF(OR(B37="",C37="",E37=""),"",C37/(B37+E37)) -> 0.38655914 | J37: =IF(OR(B37="",C37="",E37=""),"",(2*C37-B37)/E37) -> 0.64597315 | K37: =IF(OR(B37="",C37="",E37=""),"",(C37-B37)/(E37-B37)) -> 0.097328244 | L37: =IF(OR(B37="",C37="",E37=""),"",C37/(E37-B37)) -> 1.3721374 | M37: =IF(OR(B37="",C37="",E37=""),"",(B37/E37)*((C37-B37)/B37)^0.143) -> 0.3879178 | N37: =IF(OR(C37="",E37=""),"",C37/E37) -> 0.60318792 | O37: =IF(OR(B37="",C37="",E37=""),"",C37/B37+B37/E37) -> 1.63675 | P37: =IF(OR(B37="",C37="",E37=""),"",B37/C37-2*B37/(B37+E37)) -> 0.21078858 | T37: PASS
A38: =Master_Database!A38 -> MG-MIX-008 | B38: =Master_Database!F38 -> 669 | C38: =Master_Database!G38 -> 728 | D38: =Master_Database!H38 -> 0 | E38: =Master_Database!I38 -> 1188 | F38: =IF(OR(B38="",C38=""),"",C38-B38) -> 59 | G38: =IF(OR(B38="",E38=""),"",B38/E38) -> 0.56313131 | H38: =IF(OR(B38="",D38=""),"",B38/D38) | I38: =IF(OR(B38="",C38="",E38=""),"",C38/(B38+E38)) -> 0.39203016 | J38: =IF(OR(B38="",C38="",E38=""),"",(2*C38-B38)/E38) -> 0.66245791 | K38: =IF(OR(B38="",C38="",E38=""),"",(C38-B38)/(E38-B38)) -> 0.11368015 | L38: =IF(OR(B38="",C38="",E38=""),"",C38/(E38-B38)) -> 1.4026975 | M38: =IF(OR(B38="",C38="",E38=""),"",(B38/E38)*((C38-B38)/B38)^0.143) -> 0.39792899 | N38: =IF(OR(C38="",E38=""),"",C38/E38) -> 0.61279461 | O38: =IF(OR(B38="",C38="",E38=""),"",C38/B38+B38/E38) -> 1.6513226 | P38: =IF(OR(B38="",C38="",E38=""),"",B38/C38-2*B38/(B38+E38)) -> 0.19843908 | T38: PASS
... A53: =Master_Database!A53 -> MG-MIX-023 | B53: =Master_Database!F53 -> 450 | C53: =Master_Database!G53 -> 470 | D53: =Master_Database!H53 -> 0 | E53: =Master_Database!I53 -> 790 | F53: =IF(OR(B53="",C53=""),"",C53-B53) -> 20 | G53: =IF(OR(B53="",E53=""),"",B53/E53) -> 0.56962025 | H53: =IF(OR(B53="",D53=""),"",B53/D53) | I53: =IF(OR(B53="",C53="",E53=""),"",C53/(B53+E53)) -> 0.37903226 | J53: =IF(OR(B53="",C53="",E53=""),"",(2*C53-B53)/E53) -> 0.62025316 | K53: =IF(OR(B53="",C53="",E53=""),"",(C53-B53)/(E53-B53)) -> 0.058823529 | L53: =IF(OR(B53="",C53="",E53=""),"",C53/(E53-B53)) -> 1.3823529 | M53: =IF(OR(B53="",C53="",E53=""),"",(B53/E53)*((C53-B53)/B53)^0.143) -> 0.36494156 | N53: =IF(OR(C53="",E53=""),"",C53/E53) -> 0.59493671 | O53: =IF(OR(B53="",C53="",E53=""),"",C53/B53+B53/E53) -> 1.6140647 | P53: =IF(OR(B53="",C53="",E53=""),"",B53/C53-2*B53/(B53+E53)) -> 0.23164036 | T53: PASS
A54: =Master_Database!A54 -> MG-LONG-001 | B54: =Master_Database!F54 -> 709 | C54: =Master_Database!G54 -> 762 | D54: =Master_Database!H54 -> 0 | E54: =Master_Database!I54 -> 1199 | F54: =IF(OR(B54="",C54=""),"",C54-B54) -> 53 | G54: =IF(OR(B54="",E54=""),"",B54/E54) -> 0.59132611 | H54: =IF(OR(B54="",D54=""),"",B54/D54) | I54: =IF(OR(B54="",C54="",E54=""),"",C54/(B54+E54)) -> 0.39937107 | J54: =IF(OR(B54="",C54="",E54=""),"",(2*C54-B54)/E54) -> 0.67973311 | K54: =IF(OR(B54="",C54="",E54=""),"",(C54-B54)/(E54-B54)) -> 0.10816327 | L54: =IF(OR(B54="",C54="",E54=""),"",C54/(E54-B54)) -> 1.555102 | M54: =IF(OR(B54="",C54="",E54=""),"",(B54/E54)*((C54-B54)/B54)^0.143) -> 0.40809013 | N54: =IF(OR(C54="",E54=""),"",C54/E54) -> 0.63552961 | O54: =IF(OR(B54="",C54="",E54=""),"",C54/B54+B54/E54) -> 1.6660793 | P54: =IF(OR(B54="",C54="",E54=""),"",B54/C54-2*B54/(B54+E54)) -> 0.18725961 | Q54: 53 | R54: 0.59133 | S54: 0.39937 | T54: PASS; source γm=0.67973; ΔTrg=0.10816; δ=1.5551; φ=0.40809; α=0.63553; β=1.6661; βI=2.829; 1/ω=5.3402
A55: =Master_Database!A55 -> MG-LONG-002 | B55: =Master_Database!F55 -> 745 | C55: =Master_Database!G55 -> 785 | D55: =Master_Database!H55 -> 0 | E55: =Master_Database!I55 -> 1241 | F55: =IF(OR(B55="",C55=""),"",C55-B55) -> 40 | G55: =IF(OR(B55="",E55=""),"",B55/E55) -> 0.60032232 | H55: =IF(OR(B55="",D55=""),"",B55/D55) | I55: =IF(OR(B55="",C55="",E55=""),"",C55/(B55+E55)) -> 0.39526687 | J55: =IF(OR(B55="",C55="",E55=""),"",(2*C55-B55)/E55) -> 0.66478646 | K55: =IF(OR(B55="",C55="",E55=""),"",(C55-B55)/(E55-B55)) -> 0.080645161 | L55: =IF(OR(B55="",C55="",E55=""),"",C55/(E55-B55)) -> 1.5826613 | M55: =IF(OR(B55="",C55="",E55=""),"",(B55/E55)*((C55-B55)/B55)^0.143) -> 0.39514885 | N55: =IF(OR(C55="",E55=""),"",C55/E55) -> 0.63255439 | O55: =IF(OR(B55="",C55="",E55=""),"",C55/B55+B55/E55) -> 1.6540136 | P55: =IF(OR(B55="",C55="",E55=""),"",B55/C55-2*B55/(B55+E55)) -> 0.19879282 | Q55: 40 | R55: 0.60032 | S55: 0.39527 | T55: PASS; source γm=0.66479; ΔTrg=0.08065; δ=1.5827; φ=0.39515; α=0.63255; β=1.654; βI=2.8125; 1/ω=5.0304
A56: =Master_Database!A56 -> MG-LONG-003 | B56: =Master_Database!F56 -> 744 | C56: =Master_Database!G56 -> 777 | D56: =Master_Database!H56 -> 0 | E56: =Master_Database!I56 -> 1218 | F56: =IF(OR(B56="",C56=""),"",C56-B56) -> 33 | G56: =IF(OR(B56="",E56=""),"",B56/E56) -> 0.61083744 | H56: =IF(OR(B56="",D56=""),"",B56/D56) | I56: =IF(OR(B56="",C56="",E56=""),"",C56/(B56+E56)) -> 0.39602446 | J56: =IF(OR(B56="",C56="",E56=""),"",(2*C56-B56)/E56) -> 0.66502463 | K56: =IF(OR(B56="",C56="",E56=""),"",(C56-B56)/(E56-B56)) -> 0.069620253 | L56: =IF(OR(B56="",C56="",E56=""),"",C56/(E56-B56)) -> 1.6392405 | M56: =IF(OR(B56="",C56="",E56=""),"",(B56/E56)*((C56-B56)/B56)^0.143) -> 0.39123546 | N56: =IF(OR(C56="",E56=""),"",C56/E56) -> 0.63793103 | O56: =IF(OR(B56="",C56="",E56=""),"",C56/B56+B56/E56) -> 1.6551923 | P56: =IF(OR(B56="",C56="",E56=""),"",B56/C56-2*B56/(B56+E56)) -> 0.19911917 | Q56: 33 | R56: 0.61084 | S56: 0.39602 | T56: PASS; source γm=0.66502; ΔTrg=0.06962; δ=1.6392; φ=0.39124; α=0.63793; β=1.6552; βI=2.9725; 1/ω=5.0221
A57: =Master_Database!A57 -> MG-LONG-004 | B57: =Master_Database!F57 -> 736 | C57: =Master_Database!G57 -> 779 | D57: =Master_Database!H57 -> 0 | E57: =Master_Database!I57 -> 1193 | F57: =IF(OR(B57="",C57=""),"",C57-B57) -> 43 | G57: =IF(OR(B57="",E57=""),"",B57/E57) -> 0.6169321 | H57: =IF(OR(B57="",D57=""),"",B57/D57) | I57: =IF(OR(B57="",C57="",E57=""),"",C57/(B57+E57)) -> 0.40383618 | J57: =IF(OR(B57="",C57="",E57=""),"",(2*C57-B57)/E57) -> 0.68901928 | K57: =IF(OR(B57="",C57="",E57=""),"",(C57-B57)/(E57-B57)) -> 0.094091904 | L57: =IF(OR(B57="",C57="",E57=""),"",C57/(E57-B57)) -> 1.7045952 | M57: =IF(OR(B57="",C57="",E57=""),"",(B57/E57)*((C57-B57)/B57)^0.143) -> 0.41101704 | N57: =IF(OR(C57="",E57=""),"",C57/E57) -> 0.65297569 | O57: =IF(OR(B57="",C57="",E57=""),"",C57/B57+B57/E57) -> 1.675356 | P57: =IF(OR(B57="",C57="",E57=""),"",B57/C57-2*B57/(B57+E57)) -> 0.18171134 | Q57: 43 | R57: 0.61693 | S57: 0.40384 | T57: PASS; source γm=0.68902; ΔTrg=0.09409; δ=1.7046; φ=0.41102; α=0.65298; β=1.6754; βI=3.3451; 1/ω=5.5032
A58: =Master_Database!A58 -> MG-LONG-005 | B58: =Master_Database!F58 -> 733 | C58: =Master_Database!G58 -> 777 | D58: =Master_Database!H58 -> 0 | E58: =Master_Database!I58 -> 1187 | F58: =IF(OR(B58="",C58=""),"",C58-B58) -> 44 | G58: =IF(OR(B58="",E58=""),"",B58/E58) -> 0.61752317 | H58: =IF(OR(B58="",D58=""),"",B58/D58) | I58: =IF(OR(B58="",C58="",E58=""),"",C58/(B58+E58)) -> 0.4046875 | J58: =IF(OR(B58="",C58="",E58=""),"",(2*C58-B58)/E58) -> 0.69165965 | K58: =IF(OR(B58="",C58="",E58=""),"",(C58-B58)/(E58-B58)) -> 0.0969163 | L58: =IF(OR(B58="",C58="",E58=""),"",C58/(E58-B58)) -> 1.7114537 | M58: =IF(OR(B58="",C58="",E58=""),"",(B58/E58)*((C58-B58)/B58)^0.143) -> 0.41300672 | N58: =IF(OR(C58="",E58=""),"",C58/E58) -> 0.65459141 | O58: =IF(OR(B58="",C58="",E58=""),"",C58/B58+B58/E58) -> 1.6775505 | P58: =IF(OR(B58="",C58="",E58=""),"",B58/C58-2*B58/(B58+E58)) -> 0.17983028 | Q58: 44 | R58: 0.61752 | S58: 0.40469 | T58: PASS; source γm=0.69166; ΔTrg=0.09692; δ=1.7115; φ=0.41301; α=0.65459; β=1.6776; βI=3.3881; 1/ω=5.5608
A59: =Master_Database!A59 -> MG-LONG-006 | B59: =Master_Database!F59 -> 696 | C59: =Master_Database!G59 -> 746 | D59: =Master_Database!H59 -> 0 | E59: =Master_Database!I59 -> 1201 | F59: =IF(OR(B59="",C59=""),"",C59-B59) -> 50 | G59: =IF(OR(B59="",E59=""),"",B59/E59) -> 0.57951707 | H59: =IF(OR(B59="",D59=""),"",B59/D59) | I59: =IF(OR(B59="",C59="",E59=""),"",C59/(B59+E59)) -> 0.3932525 | J59: =IF(OR(B59="",C59="",E59=""),"",(2*C59-B59)/E59) -> 0.66278102 | K59: =IF(OR(B59="",C59="",E59=""),"",(C59-B59)/(E59-B59)) -> 0.099009901 | L59: =IF(OR(B59="",C59="",E59=""),"",C59/(E59-B59)) -> 1.4772277 | M59: =IF(OR(B59="",C59="",E59=""),"",(B59/E59)*((C59-B59)/B59)^0.143) -> 0.39767274 | N59: =IF(OR(C59="",E59=""),"",C59/E59) -> 0.62114904 | O59: =IF(OR(B59="",C59="",E59=""),"",C59/B59+B59/E59) -> 1.6513561 | P59: =IF(OR(B59="",C59="",E59=""),"",B59/C59-2*B59/(B59+E59)) -> 0.19918568 | Q59: 50 | R59: 0.57952 | S59: 0.39325 | T59: PASS; source γm=0.66278; ΔTrg=0.09901; δ=1.4772; φ=0.39767; α=0.62115; β=1.6514; βI=2.508; 1/ω=5.0204
A60: =Master_Database!A60 -> MG-LONG-007 | B60: =Master_Database!F60 -> 705 | C60: =Master_Database!G60 -> 781 | D60: =Master_Database!H60 -> 0 | E60: =Master_Database!I60 -> 1163 | F60: =IF(OR(B60="",C60=""),"",C60-B60) -> 76 | G60: =IF(OR(B60="",E60=""),"",B60/E60) -> 0.60619089 | H60: =IF(OR(B60="",D60=""),"",B60/D60) | I60: =IF(OR(B60="",C60="",E60=""),"",C60/(B60+E60)) -> 0.41809422 | J60: =IF(OR(B60="",C60="",E60=""),"",(2*C60-B60)/E60) -> 0.73688736 | K60: =IF(OR(B60="",C60="",E60=""),"",(C60-B60)/(E60-B60)) -> 0.16593886 | L60: =IF(OR(B60="",C60="",E60=""),"",C60/(E60-B60)) -> 1.7052402 | M60: =IF(OR(B60="",C60="",E60=""),"",(B60/E60)*((C60-B60)/B60)^0.143) -> 0.44083361 | N60: =IF(OR(C60="",E60=""),"",C60/E60) -> 0.67153912 | O60: =IF(OR(B60="",C60="",E60=""),"",C60/B60+B60/E60) -> 1.7139923 | P60: =IF(OR(B60="",C60="",E60=""),"",B60/C60-2*B60/(B60+E60)) -> 0.14787087 | Q60: 76 | R60: 0.60619 | S60: 0.41809 | T60: PASS; source γm=0.73689; ΔTrg=0.16594; δ=1.7052; φ=0.44083; α=0.67154; β=1.714; βI=3.7732; 1/ω=6.7627
A61: =Master_Database!A61 -> MG-LONG-008 | B61: =Master_Database!F61 -> 665 | C61: =Master_Database!G61 -> 743 | D61: =Master_Database!H61 -> 0 | E61: =Master_Database!I61 -> 1118 | F61: =IF(OR(B61="",C61=""),"",C61-B61) -> 78 | G61: =IF(OR(B61="",E61=""),"",B61/E61) -> 0.59481216 | H61: =IF(OR(B61="",D61=""),"",B61/D61) | I61: =IF(OR(B61="",C61="",E61=""),"",C61/(B61+E61)) -> 0.4167134 | J61: =IF(OR(B61="",C61="",E61=""),"",(2*C61-B61)/E61) -> 0.73434705 | K61: =IF(OR(B61="",C61="",E61=""),"",(C61-B61)/(E61-B61)) -> 0.17218543 | L61: =IF(OR(B61="",C61="",E61=""),"",C61/(E61-B61)) -> 1.6401766 | M61: =IF(OR(B61="",C61="",E61=""),"",(B61/E61)*((C61-B61)/B61)^0.143) -> 0.4378102 | N61: =IF(OR(C61="",E61=""),"",C61/E61) -> 0.66457961 | O61: =IF(OR(B61="",C61="",E61=""),"",C61/B61+B61/E61) -> 1.7121054 | P61: =IF(OR(B61="",C61="",E61=""),"",B61/C61-2*B61/(B61+E61)) -> 0.14908637 | Q61: 78 | R61: 0.59481 | S61: 0.41671 | T61: PASS; source γm=0.73435; ΔTrg=0.17219; δ=1.6402; φ=0.43781; α=0.66458; β=1.7121; βI=3.5136; 1/ω=6.7075
A62: =Master_Database!A62 -> MG-LONG-009 | B62: =Master_Database!F62 -> 693 | C62: =Master_Database!G62 -> 770 | D62: =Master_Database!H62 -> 0 | E62: =Master_Database!I62 -> 1143 | F62: =IF(OR(B62="",C62=""),"",C62-B62) -> 77 | G62: =IF(OR(B62="",E62=""),"",B62/E62) -> 0.60629921 | H62: =IF(OR(B62="",D62=""),"",B62/D62) | I62: =IF(OR(B62="",C62="",E62=""),"",C62/(B62+E62)) -> 0.41938998 | J62: =IF(OR(B62="",C62="",E62=""),"",(2*C62-B62)/E62) -> 0.74103237 | K62: =IF(OR(B62="",C62="",E62=""),"",(C62-B62)/(E62-B62)) -> 0.17111111 | L62: =IF(OR(B62="",C62="",E62=""),"",C62/(E62-B62)) -> 1.7111111 | M62: =IF(OR(B62="",C62="",E62=""),"",(B62/E62)*((C62-B62)/B62)^0.143) -> 0.44282316 | N62: =IF(OR(C62="",E62=""),"",C62/E62) -> 0.67366579 | O62: =IF(OR(B62="",C62="",E62=""),"",C62/B62+B62/E62) -> 1.7174103 | P62: =IF(OR(B62="",C62="",E62=""),"",B62/C62-2*B62/(B62+E62)) -> 0.14509804 | Q62: 77 | R62: 0.6063 | S62: 0.41939 | T62: PASS; source γm=0.74103; ΔTrg=0.17111; δ=1.7111; φ=0.44282; α=0.67367; β=1.7174; βI=3.8354; 1/ω=6.8919
A63: =Master_Database!A63 -> MG-LONG-010 | B63: =Master_Database!F63 -> 672 | C63: =Master_Database!G63 -> 772 | D63: =Master_Database!H63 -> 0 | E63: =Master_Database!I63 -> 1113 | F63: =IF(OR(B63="",C63=""),"",C63-B63) -> 100 | G63: =IF(OR(B63="",E63=""),"",B63/E63) -> 0.60377358 | H63: =IF(OR(B63="",D63=""),"",B63/D63) | I63: =IF(OR(B63="",C63="",E63=""),"",C63/(B63+E63)) -> 0.432493 | J63: =IF(OR(B63="",C63="",E63=""),"",(2*C63-B63)/E63) -> 0.7834681 | K63: =IF(OR(B63="",C63="",E63=""),"",(C63-B63)/(E63-B63)) -> 0.22675737 | L63: =IF(OR(B63="",C63="",E63=""),"",C63/(E63-B63)) -> 1.7505669 | M63: =IF(OR(B63="",C63="",E63=""),"",(B63/E63)*((C63-B63)/B63)^0.143) -> 0.45979083 | N63: =IF(OR(C63="",E63=""),"",C63/E63) -> 0.69362084 | O63: =IF(OR(B63="",C63="",E63=""),"",C63/B63+B63/E63) -> 1.7525831 | P63: =IF(OR(B63="",C63="",E63=""),"",B63/C63-2*B63/(B63+E63)) -> 0.11752514 | Q63: 100 | R63: 0.60377 | S63: 0.43249 | T63: PASS; source γm=0.78347; ΔTrg=0.22676; δ=1.7506; φ=0.45979; α=0.69362; β=1.7526; βI=4.4615; 1/ω=8.5088
A64: =Master_Database!A64 -> MG-LONG-011 | B64: =Master_Database!F64 -> 380 | C64: =Master_Database!G64 -> 400 | D64: =Master_Database!H64 -> 0 | E64: =Master_Database!I64 -> 666 | F64: =IF(OR(B64="",C64=""),"",C64-B64) -> 20 | G64: =IF(OR(B64="",E64=""),"",B64/E64) -> 0.57057057 | H64: =IF(OR(B64="",D64=""),"",B64/D64) | I64: =IF(OR(B64="",C64="",E64=""),"",C64/(B64+E64)) -> 0.38240918 | J64: =IF(OR(B64="",C64="",E64=""),"",(2*C64-B64)/E64) -> 0.63063063 | K64: =IF(OR(B64="",C64="",E64=""),"",(C64-B64)/(E64-B64)) -> 0.06993007 | L64: =IF(OR(B64="",C64="",E64=""),"",C64/(E64-B64)) -> 1.3986014 | M64: =IF(OR(B64="",C64="",E64=""),"",(B64/E64)*((C64-B64)/B64)^0.143) -> 0.37449636 | N64: =IF(OR(C64="",E64=""),"",C64/E64) -> 0.6006006 | O64: =IF(OR(B64="",C64="",E64=""),"",C64/B64+B64/E64) -> 1.6232021 | P64: =IF(OR(B64="",C64="",E64=""),"",B64/C64-2*B64/(B64+E64)) -> 0.22342256 | Q64: 20 | R64: 0.57057 | S64: 0.38241 | T64: PASS; source γm=0.63063; ΔTrg=0.06993; δ=1.3986; φ=0.3745; α=0.6006; β=1.6232; βI=2.1482; 1/ω=4.4758
A65: =Master_Database!A65 -> MG-LONG-012 | B65: =Master_Database!F65 -> 375 | C65: =Master_Database!G65 -> 412 | D65: =Master_Database!H65 -> 0 | E65: =Master_Database!I65 -> 640 | F65: =IF(OR(B65="",C65=""),"",C65-B65) -> 37 | G65: =IF(OR(B65="",E65=""),"",B65/E65) -> 0.5859375 | H65: =IF(OR(B65="",D65=""),"",B65/D65) | I65: =IF(OR(B65="",C65="",E65=""),"",C65/(B65+E65)) -> 0.40591133 | J65: =IF(OR(B65="",C65="",E65=""),"",(2*C65-B65)/E65) -> 0.7015625 | K65: =IF(OR(B65="",C65="",E65=""),"",(C65-B65)/(E65-B65)) -> 0.13962264 | L65: =IF(OR(B65="",C65="",E65=""),"",C65/(E65-B65)) -> 1.554717 | M65: =IF(OR(B65="",C65="",E65=""),"",(B65/E65)*((C65-B65)/B65)^0.143) -> 0.42074375 | N65: =IF(OR(C65="",E65=""),"",C65/E65) -> 0.64375 | O65: =IF(OR(B65="",C65="",E65=""),"",C65/B65+B65/E65) -> 1.6846042 | P65: =IF(OR(B65="",C65="",E65=""),"",B65/C65-2*B65/(B65+E65)) -> 0.17127792 | T65: PASS
A66: =Master_Database!A66 -> MG-LONG-013 | B66: =Master_Database!F66 -> 387 | C66: =Master_Database!G66 -> 405 | D66: =Master_Database!H66 -> 0 | E66: =Master_Database!I66 -> 759 | F66: =IF(OR(B66="",C66=""),"",C66-B66) -> 18 | G66: =IF(OR(B66="",E66=""),"",B66/E66) -> 0.50988142 | H66: =IF(OR(B66="",D66=""),"",B66/D66) | I66: =IF(OR(B66="",C66="",E66=""),"",C66/(B66+E66)) -> 0.35340314 | J66: =IF(OR(B66="",C66="",E66=""),"",(2*C66-B66)/E66) -> 0.55731225 | K66: =IF(OR(B66="",C66="",E66=""),"",(C66-B66)/(E66-B66)) -> 0.048387097 | L66: =IF(OR(B66="",C66="",E66=""),"",C66/(E66-B66)) -> 1.0887097 | M66: =IF(OR(B66="",C66="",E66=""),"",(B66/E66)*((C66-B66)/B66)^0.143) -> 0.328799 | N66: =IF(OR(C66="",E66=""),"",C66/E66) -> 0.53359684 | O66: =IF(OR(B66="",C66="",E66=""),"",C66/B66+B66/E66) -> 1.5563931 | P66: =IF(OR(B66="",C66="",E66=""),"",B66/C66-2*B66/(B66+E66)) -> 0.28016289 | T66: PASS
...

Sheet Source_by_Source
A1: Source_ID | B1: Draft_ref | C1: Alloy_family_or_role | D1: Citation | E1: DOI | F1: Primary_URL | G1: Verification_status | H1: Data_expected | I1: Audit_note
A2: SRC20 | B2: [20] | C2: Cu–Zr–Al / cluster-resonance context | D2: G. Han et al., Philosophical Magazine 91 (2011) 2404–2418 | E2: 10.1080/14786435.2011.558524 | F2: https://doi.org/10.1080/14786435.2011.558524 | G2: DOI_VERIFIED | H2: Composition formulae; Cu–Zr–Al and B–Co–Si–Ta examples | I2: Bibliographic DOI verified; numerical row extraction still pending primary full-table audit.
A3: SRC21 | B3: [21] | C3: Zr–Ni–Al | D3: F.W. Li et al., Chinese Science Bulletin 56 (2011) 3902–3907 | E3: 10.1007/s11434-011-4842-z | F3: https://link.springer.com/article/10.1007/s11434-011-4842-z | G3: PRIMARY_OPEN_ACCESS_TABLE_EXTRACTED | H3: 25 Table-1 rows extracted: Tg, Tx, Tm, Tl, reported ΔTx, Trg and γm available; dc requires separate figure audit. | I3: Table 1 (p.3906) transcribed into Master_Database. Source table has 25 rows including the reference alloy, whereas the draft family count says N=22; discrepancy flagged.
A4: SRC23 | B4: [23] | C4: Co–B–Si–Ta | D4: C.L. Zhu et al., Journal of Alloys and Compounds 504 (2010) S34–S37 | E4: 10.1016/j.jallcom.2010.04.065 | F4: https://doi.org/10.1016/j.jallcom.2010.04.065 | G4: PRIMARY_PUBLISHER_ABSTRACT | H4: Compositions, casting diameters, thermal/mechanical data | I4: Publisher confirms Co62.2B26.9Si6.9Ta4 forms 4 mm amorphous rod; full thermal table extraction pending.
A5: SRC24 | B5: [24] | C5: B–Ni–Fe–Si–Ta | D5: C.L. Zhu et al., Intermetallics 18 (2010) 791–795 | E5: 10.1016/j.intermet.2009.12.007 | F5: https://doi.org/10.1016/j.intermet.2009.12.007 | G5: DOI_VERIFIED_SECONDARY_ABSTRACT | H5: Compositions, dc, thermal data | I5: DOI and abstract metadata located; primary full table still required before VERIFIED_PRIMARY row values.
A6: SRC25 | B6: [25] | C6: Ni–Nb–Zr | D6: L. Yuan et al., Intermetallics 18 (2010) 1800–1802 | E6: 10.1016/j.intermet.2010.01.023 | F6: https://doi.org/10.1016/j.intermet.2010.01.023 | G6: DOI_VERIFIED_SECONDARY_ABSTRACT | H6: Ni–Nb–Zr compositions and 3 mm rods | I6: Abstract reports x=0.76–1.16 compositions forming single glassy phases in 3 mm rods; full thermal values pending.
A7: SRC27 | B7: [27] | C7: Mixed BMG / Trg criterion | D7: Z.P. Lu et al., Scripta Materialia 42 (2000) 667–673 | E7: 10.1016/S1359-6462(99)00417-0 | F7: https://doi.org/10.1016/S1359-6462(99)00417-0 | G7: PRIMARY_PUBLISHER_ABSTRACT | H7: Zr-, La-, Mg-, Pd-, RE-based thermal/GFA comparison | I7: DOI verified at publisher; table extraction required.
A8: SRC29 | B8: [29] | C8: RE-based | D8: S. Li et al., Journal of Non-Crystalline Solids 354 (2008) 1080–1088 | E8: 10.1016/j.jnoncrysol.2007.08.022 | F8: https://doi.org/10.1016/j.jnoncrysol.2007.08.022 | G8: PRIMARY_PUBLISHER_ABSTRACT | H8: RE55Al25Co20 series: GFA, thermal, elastic/mechanical properties | I8: DOI and family verified; full table extraction pending.
A9: SRC30 | B9: [30] | C9: Mixed BMG / alternative GFA criteria | D9: Z. Long et al., Journal of Alloys and Compounds 475 (2009) 207–219 | E9: 10.1016/j.jallcom.2008.07.087 | F9: https://doi.org/10.1016/j.jallcom.2008.07.087 | G9: PRIMARY_PUBLISHER_ABSTRACT | H9: Large compiled BMG thermal dataset; ω and other GFA criteria | I9: Publisher verifies formulas for ω, Trg, ΔTx, γ, γm, ΔTrg, δ, φ, α and β; full data table extraction pending.
A10: SRC32 | B10: [32] | C10: La-based / γ limitation | D10: Z.P. Lu et al., Intermetallics 16 (2008) 410–417 | E10: 10.1016/j.intermet.2007.12.002 | F10: https://doi.org/10.1016/j.intermet.2007.12.002 | G10: PRIMARY_PUBLISHER_ABSTRACT | H10: La-based compositions; γ=Tx/(Tg+Tl); GFA limitations | I10: Publisher verifies γ definition and chemistry-dependent limitations.
A11: SRC33 | B11: Expansion | C11: Cu–Zr–Al | D11: G. Wang et al., Materials Research 22 (2019) e20190078 | E11: 10.1590/1980-5373-MR-2019-0078 | F11: https://doi.org/10.1590/1980-5373-MR-2019-0078 | G11: PRIMARY_OPEN_ACCESS_TABLE_EXTRACTED | H11: Tg, Tx, ΔTx, Tl, Trg, γ, Dc for four Cu–Zr–Al(-Y,-Nb) compositions | I11: Four explicit rows added to Master_Database as VERIFIED_PRIMARY.
A12: SRC34 | B12: Expansion | C12: Mixed BMG / GFA criteria | D12: Q. Chen et al., Materials Science and Engineering A 433 (2006) 155–160 | E12: 10.1016/j.msea.2006.06.053 | F12: https://doi.org/10.1016/j.msea.2006.06.053 | G12: COMPILATION_TABLE_EXTRACTED | H12: Tg, Tx, Tl, Dmax, Trg, γ and δ for reported BMGs | I12: Publisher DOI corrected to 10.1016/j.msea.2006.06.053. Selected explicit rows staged; cited primary references remain to be audited.
A13: SRC35 | B13: Expansion | C13: Ni-based BMGs | D13: Synthesis of Ni-Based Bulk Metallic Glasses for Penetrating Materials (accessible full report) | F13: https://lab.hanbat.ac.kr/ajaajaaja/theses/document/1856/download | G13: PRIMARY_FULL_REPORT_TABLE_EXTRACTED | H13: Tg, Tx, ΔTx, Tl, Trg, ΔH and maximum diameter for base/Al/W/Hf-modified alloys | I13: Four explicit Ni-based rows added; bibliographic journal mapping/DOI still to be resolved.
A14: SRC36 | B14: Expansion / independent compilation | C14: Ag-, Cu-, Fe-, Gd-, La-, Mg-, Ti-, Zr-based BMGs | D14: Z. Long et al., Journal of Thermal Analysis and Calorimetry 132 (2018) 1645–1660 | E14: 10.1007/s10973-018-7050-0 | F14: https://doi.org/10.1007/s10973-018-7050-0 | G14: FULL_TEXT_TABLE_PARTIALLY_EXTRACTED | H14: Table 2: Tg, Tx, Tl and Dmax for reported BMGs; first 17 Ag-rich rows extracted in this run. | I14: Useful independent compilation for approaching target coverage and cross-checking older compilations; rows remain Include_model=NO until primary cited reference is locked.
